<?xml version='1.0' encoding='utf-8'?>

<robot name="dual_arm_mobile">



	<!-- RIGHT ARM -->
<!-- 
      <link name="shoulder">
      <inertial>
        <origin xyz="0 0 0.05" rpy="0 0 0" />
        <mass value="4" />
        <inertia ixx="0.4" iyy="0.4" izz="0.4" ixy="0" ixz="0" iyz="0" />
      </inertial>
      <visual>
          <origin xyz="2.0 2.0 2.0" rpy="0 0 0" />
            <geometry>
                <mesh filename="../../../Model/meshes/visual/link1.obj"/>
            </geometry>
       </visual>
    </link> -->

     

	 <link name="link0R">
      <inertial>
        <origin xyz="0 0 0.05" rpy="0 0 0" />
        <mass value="4" />
        <inertia ixx="0.4" iyy="0.4" izz="0.4" ixy="0" ixz="0" iyz="0" />
      </inertial>
      <visual>
        <geometry>
          <mesh filename="../../../Model/meshes/visual/link0.obj"/>
        </geometry>
      </visual>
<!--       <collision>
        <geometry>
          <mesh filename="../../../Model/meshes/collision/link0.obj"/>
        </geometry>
      </collision> -->
    </link>

    <link name="link1R">
      <inertial>
        <origin xyz="0 0 -0.07" rpy="0 -0 0" />
        <mass value="3" />
        <inertia ixx="0.3" iyy="0.3" izz="0.3" ixy="0" ixz="0" iyz="0" />
      </inertial>
      <visual>
        <geometry>
          <mesh filename="../../../Model/meshes/visual/link1.obj"/>
        </geometry>
      </visual>
      <!-- <collision>
        <geometry>
          <mesh filename="../../../Model/meshes/collision/link1.obj"/>
        </geometry>
      </collision> -->
    </link>

    <link name="link2R">
      <inertial>
        <origin xyz="0 -0.1 0" rpy="0 -0 0" />
        <mass value="3" />
        <inertia ixx="0.3" iyy="0.3" izz="0.3" ixy="0" ixz="0" iyz="0" />
      </inertial>
      <visual>
        <geometry>
          <mesh filename="../../../Model/meshes/visual/link2.obj"/>
        </geometry>
      </visual>
      <!-- <collision>
        <geometry>
          <mesh filename="../../../Model/meshes/collision/link2.obj"/>
        </geometry>
      </collision> -->
    </link>
    <link name="link3R">
      <inertial>
        <origin xyz="0.04 0 -0.05" rpy="0 -0 0" />
        <mass value="2" />
        <inertia ixx="0.2" iyy="0.2" izz="0.2" ixy="0" ixz="0" iyz="0" />
      </inertial>
      <visual>
        <geometry>
          <mesh filename="../../../Model/meshes/visual/link3.obj"/>
        </geometry>
      </visual>
      <!-- <collision>
        <geometry>
          <mesh filename="../../../Model/meshes/collision/link3.obj"/>
        </geometry>
      </collision> -->
    </link>
    <link name="link4R">
      <inertial>
        <origin xyz="-0.04 0.05 0" rpy="0 -0 0" />
        <mass value="2" />
        <inertia ixx="0.2" iyy="0.2" izz="0.2" ixy="0" ixz="0" iyz="0" />
      </inertial>
      <visual>
        <geometry>
          <mesh filename="../../../Model/meshes/visual/link4.obj"/>
        </geometry>
      </visual>
      <collision>
        <geometry>
          <mesh filename="../../../Model/meshes/collision/link4.obj"/>
        </geometry>
      </collision>
    </link>
    <link name="link5R">
      <inertial>
        <origin xyz="0 0 -0.15" rpy="0 -0 0" />
        <mass value="2" />
        <inertia ixx="0.2" iyy="0.2" izz="0.2" ixy="0" ixz="0" iyz="0" />
      </inertial>
      <visual>
        <geometry>
          <mesh filename="../../../Model/meshes/visual/link5.obj"/>
        </geometry>
      </visual>
<!--       <collision>
        <geometry>
          <mesh filename="../../../Model/meshes/collision/link5.obj"/>
        </geometry>
      </collision> -->
    </link>
    <link name="link6R">
      <inertial>
        <origin xyz="0.06 0 0" rpy="0 -0 0" />
        <mass value="1.5" />
        <inertia ixx="0.1" iyy="0.1" izz="0.1" ixy="0" ixz="0" iyz="0" />
      </inertial>
      <visual>
        <geometry>
          <mesh filename="../../../Model/meshes/visual/link6.obj"/>
        </geometry>
      </visual>
      <!-- <collision>
        <geometry>
          <mesh filename="../../../Model/meshes/collision/link6.obj"/>
        </geometry>
      </collision> -->
    </link>
    <link name="link7R">
      <inertial>
        <origin xyz="0 0 0.17" rpy="0 -0 0" />
        <mass value="1.8" />
        <inertia ixx="0.09" iyy="0.05" izz="0.07" ixy="0" ixz="0" iyz="0" />
      </inertial>
      <visual>
        <geometry>
          <mesh filename="../../../Model/meshes/visual/link7.obj"/>
        </geometry>
      </visual>
      <!-- <collision>
        <geometry>
          <mesh filename="../../../Model/meshes/collision/link7.obj"/>
        </geometry>
      </collision> -->
      <visual>
        <origin xyz="0 0 0.107" rpy="0 0 -0.78539816339" />
        <geometry>
          <mesh filename="../../../Model/meshes/visual/hand.obj"/>
        </geometry>
      </visual>
<!--       <collision>
        <origin xyz="0 0 0.107" rpy="0 0 -0.78539816339" />
        <geometry>
          <mesh filename="../../../Model/meshes/collision/hand.obj"/>
        </geometry>
      </collision> -->
    </link>
    <link name="leftfingerR">
      <inertial>
        <origin xyz="0 0 0.05" rpy="0 -0 0" />
        <mass value="0.1" />
        <inertia ixx="0.01" iyy="0.01" izz="0.005" ixy="0" ixz="0" iyz="0" />
      </inertial>
      <visual>
        <geometry>
          <mesh filename="../../../Model/meshes/visual/finger.obj"/>
        </geometry>
      </visual>
<!--       <collision>
        <geometry>
          <mesh filename="../../../Model/meshes/collision/finger.obj"/>
        </geometry>
      </collision> -->
    </link>
    <link name="rightfingerR">
      <inertial>
        <origin xyz="0 0 0.05" rpy="0 -0 0" />
        <mass value="0.1" />
        <inertia ixx="0.01" iyy="0.01" izz="0.005" ixy="0" ixz="0" iyz="0" />
      </inertial>
      <visual>
        <origin xyz="0 0 0" rpy="0 0 3.14159265359" />
        <geometry>
          <mesh filename="../../../Model/meshes/visual/finger.obj"/>
        </geometry>
      </visual>
<!--       <collision>
        <origin xyz="0 0 0" rpy="0 0 3.14159265359" />
        <geometry>
          <mesh filename="../../../Model/meshes/collision/finger.obj"/>
        </geometry>
      </collision> -->
    </link>

    <!-- <joint name="shouldertorightarm" type="fixed">
      <parent link="shoulder"/>
      <child link="link0R"/>
      <origin xyz="0 0 0.0" rpy="0 0 0"/>
    </joint> -->

    <joint name="joint1R" type="revolute">
      <safety_controller k_position="100.0" k_velocity="40.0" soft_lower_limit="-2.8973" soft_upper_limit="2.8973"/>
      <origin rpy="0 0 0" xyz="0 0 0.333"/>
      <parent link="link0R"/>
      <child link="link1R"/>
      <axis xyz="0 0 1"/>
      <limit effort="87" lower="-2.8973" upper="2.8973" velocity="2.1750"/>
    </joint>

    <joint name="joint2R" type="revolute">
      <safety_controller k_position="100.0" k_velocity="40.0" soft_lower_limit="-1.7628" soft_upper_limit="1.7628"/>
      <origin rpy="-1.57079632679 0 0" xyz="0 0 0"/>
      <parent link="link1R"/>
      <child link="link2R"/>
      <axis xyz="0 0 1"/>
      <calibration falling="15.0" />
      <limit effort="87" lower="-1.7628" upper="1.7628" velocity="2.1750"/>
    </joint>

    <joint name="joint3R" type="revolute">
      <safety_controller k_position="100.0" k_velocity="40.0" soft_lower_limit="-2.8973" soft_upper_limit="2.8973"/>
      <origin rpy="1.57079632679 0 0" xyz="0 -0.316 0"/>
      <parent link="link2R"/>
      <child link="link3R"/>
      <axis xyz="0 0 1"/>
      <limit effort="87" lower="-2.8973" upper="2.8973" velocity="2.1750"/>
    </joint>

    <joint name="joint4R" type="revolute">
      <safety_controller k_position="100.0" k_velocity="40.0" soft_lower_limit="-3.0718" soft_upper_limit="-0.0698"/>
      <origin rpy="1.57079632679 0 0" xyz="0.0825 0 0"/>
      <parent link="link3R"/>
      <child link="link4R"/>
      <axis xyz="0 0 1"/>
      <calibration falling="-95.0" />
      <limit effort="87" lower="-3.0718" upper="-0.0698" velocity="2.1750"/>
    </joint>

    <joint name="joint5R" type="revolute">
      <safety_controller k_position="100.0" k_velocity="40.0" soft_lower_limit="-2.8973" soft_upper_limit="2.8973"/>
      <origin rpy="-1.57079632679 0 0" xyz="-0.0825 0.384 0"/>
      <parent link="link4R"/>
      <child link="link5R"/>
      <axis xyz="0 0 1"/>
      <limit effort="12" lower="-2.8973" upper="2.8973" velocity="2.6100"/>
    </joint>

    <joint name="joint6R" type="revolute">
      <safety_controller k_position="100.0" k_velocity="40.0" soft_lower_limit="-0.0175" soft_upper_limit="3.7525"/>
      <origin rpy="1.57079632679 0 0" xyz="0 0 0"/>
      <parent link="link5R"/>
      <child link="link6R"/>
      <axis xyz="0 0 1"/>
      <calibration falling="125.0" />
      <limit effort="12" lower="-0.0175" upper="3.7525" velocity="2.6100"/>
    </joint>

    <joint name="joint7R" type="revolute">
      <safety_controller k_position="100.0" k_velocity="40.0" soft_lower_limit="-2.8973" soft_upper_limit="2.8973"/>
      <origin rpy="1.57079632679 0 0" xyz="0.088 0 0"/>
      <parent link="link6R"/>
      <child link="link7R"/>
      <axis xyz="0 0 1"/>
      <limit effort="12" lower="-2.8973" upper="2.8973" velocity="2.6100"/>
    </joint>

    <joint name="finger_joint1R" type="prismatic">
      <parent link="link7R"/>
      <child link="leftfingerR"/>
      <origin xyz="0 0 0.1654" rpy="0 0 -0.78539816339"/>
      <axis xyz="0 1 0"/>
      <calibration rising="0.02" />
      <limit effort="20" lower="0.0" upper="0.04" velocity="0.2"/>
    </joint>

    <joint name="finger_joint2R" type="prismatic">
      <parent link="link7R"/>
      <child link="rightfingerR"/>
      <origin xyz="0 0 0.1654" rpy="0 0 -0.78539816339"/>
      <axis xyz="0 1 0"/>
      <calibration rising="-0.02" />
      <limit effort="20" lower="0.0" upper="0.04" velocity="0.2"/>
      <!-- <mimic joint="finger_joint1" /> -->
    </joint>

   
    


    <!-- LEFT ARM -->

    



 </robot>