<?xml version='1.0' encoding='utf-8'?>

<robot
  name="mobilebase">


  <link
    name="floor">
    <inertial>
      <origin
        xyz="0.0 0.0 0.0"
        rpy="0 0 0" />
      <mass
        value="1" />
      <inertia
        ixx="0.1"
        ixy="0.1"
        ixz="0.1"
        iyy="0.1"
        iyz="0.1"
        izz="0.1" />
    </inertial>   
    </link>


    <link
    name="base_x">
    <inertial>
      <origin
        xyz="0.0 0.0 0.0"
        rpy="0 0 0" />
      <mass
        value="1" />
      <inertia
        ixx="0.1"
        ixy="0.1"
        ixz="0.1"
        iyy="0.1"
        iyz="0.1"
        izz="0.1" />
    </inertial>    
    </link>

 <link
    name="base_y">
    <inertial>
      <origin
        xyz="0.0 0.0 0.0"
        rpy="0 0 0" />
      <mass
        value="1" />
      <inertia
        ixx="0.1"
        ixy="0.1"
        ixz="0.1"
        iyy="0.1"
        iyz="0.1"
        izz="0.1" />
    </inertial>    
    </link>

<!--   FROM SOLIDWORKS MODEL
 -->

 <link
    name="base_link">
    <inertial>
      <origin
        xyz="2.2204E-16 8.3267E-17 0.34912"
        rpy="0 0 0" />
      <mass
        value="38.152" />
      <inertia
        ixx="1.218"
        ixy="-7.8787E-16"
        ixz="-7.0277E-16"
        iyy="1.218"
        iyz="1.3343E-15"
        izz="0.33133" />
    </inertial>
    <visual>
      <origin
        xyz="0 0 0"
        rpy="0 0 0" />
      <geometry>
        <mesh
          filename="../../../Model/mobilebase/meshes/base_link.obj" />
      </geometry>
      <material
        name="">
        <color
          rgba="0.79216 0.81961 0.93333 1" />
      </material>
    </visual>
   <!--  <collision>
      <origin
        xyz="0 0 0"
        rpy="0 0 0" />
      <geometry>
        <mesh
          filename="package://mobilebasev2/meshes/base_link.STL" />
      </geometry>
    </collision> -->
  </link>


  <link
    name="torso">
    <inertial>
      <origin
        xyz="-0.004232 0.0018923 1.0449"
        rpy="0 0 0" />
      <mass
        value="8.5025" />
      <inertia
        ixx="0"
        ixy="0"
        ixz="0"
        iyy="0"
        iyz="0"
        izz="0" />
    </inertial>
    <visual>
      <origin
        xyz="0 0 0"
        rpy="0 0 0" />
      <geometry>
        <mesh
          filename="../../../Model/mobilebase/meshes/torso.obj" />
      </geometry>
      <material
        name="">
        <color
          rgba="0.79216 0.81961 0.93333 1" />
      </material>
    </visual>
    <!-- <collision>
      <origin
        xyz="0 0 0"
        rpy="0 0 0" />
      <geometry>
        <mesh
          filename="package://mobilebasev2/meshes/torso.STL" />
      </geometry>
    </collision> -->
  </link>


<!--   END SOLIDOWORKS MODEL
 -->

   <!-- RIGHT ARM
 -->
 
 <link name="link0R">
      <inertial>
        <origin xyz="0 0 0.05" rpy="0 0 0" />
        <mass value="4" />
        <inertia ixx="0.4" iyy="0.4" izz="0.4" ixy="0" ixz="0" iyz="0" />
      </inertial>
      <visual>
        <geometry>
          <mesh filename="../../../Model/meshes/visual/link0.obj"/>
        </geometry>
      </visual>
<!--       <collision>
        <geometry>
          <mesh filename="../../../Model/meshes/collision/link0.obj"/>
        </geometry>
      </collision> -->
    </link>

    <link name="link1R">
      <inertial>
        <origin xyz="0 0 -0.07" rpy="0 -0 0" />
        <mass value="3" />
        <inertia ixx="0.3" iyy="0.3" izz="0.3" ixy="0" ixz="0" iyz="0" />
      </inertial>
      <visual>
        <geometry>
          <mesh filename="../../../Model/meshes/visual/link1.obj"/>
        </geometry>
      </visual>
      <!-- <collision>
        <geometry>
          <mesh filename="../../../Model/meshes/collision/link1.obj"/>
        </geometry>
      </collision> -->
    </link>

    <link name="link2R">
      <inertial>
        <origin xyz="0 -0.1 0" rpy="0 -0 0" />
        <mass value="3" />
        <inertia ixx="0.3" iyy="0.3" izz="0.3" ixy="0" ixz="0" iyz="0" />
      </inertial>
      <visual>
        <geometry>
          <mesh filename="../../../Model/meshes/visual/link2.obj"/>
        </geometry>
      </visual>
      <!-- <collision>
        <geometry>
          <mesh filename="../../../Model/meshes/collision/link2.obj"/>
        </geometry>
      </collision> -->
    </link>
    <link name="link3R">
      <inertial>
        <origin xyz="0.04 0 -0.05" rpy="0 -0 0" />
        <mass value="2" />
        <inertia ixx="0.2" iyy="0.2" izz="0.2" ixy="0" ixz="0" iyz="0" />
      </inertial>
      <visual>
        <geometry>
          <mesh filename="../../../Model/meshes/visual/link3.obj"/>
        </geometry>
      </visual>
      <!-- <collision>
        <geometry>
          <mesh filename="../../../Model/meshes/collision/link3.obj"/>
        </geometry>
      </collision> -->
    </link>
    <link name="link4R">
      <inertial>
        <origin xyz="-0.04 0.05 0" rpy="0 -0 0" />
        <mass value="2" />
        <inertia ixx="0.2" iyy="0.2" izz="0.2" ixy="0" ixz="0" iyz="0" />
      </inertial>
      <visual>
        <geometry>
          <mesh filename="../../../Model/meshes/visual/link4.obj"/>
        </geometry>
      </visual>
      <collision>
        <geometry>
          <mesh filename="../../../Model/meshes/collision/link4.obj"/>
        </geometry>
      </collision>
    </link>
    <link name="link5R">
      <inertial>
        <origin xyz="0 0 -0.15" rpy="0 -0 0" />
        <mass value="2" />
        <inertia ixx="0.2" iyy="0.2" izz="0.2" ixy="0" ixz="0" iyz="0" />
      </inertial>
      <visual>
        <geometry>
          <mesh filename="../../../Model/meshes/visual/link5.obj"/>
        </geometry>
      </visual>
<!--       <collision>
        <geometry>
          <mesh filename="../../../Model/meshes/collision/link5.obj"/>
        </geometry>
      </collision> -->
    </link>
    <link name="link6R">
      <inertial>
        <origin xyz="0.06 0 0" rpy="0 -0 0" />
        <mass value="1.5" />
        <inertia ixx="0.1" iyy="0.1" izz="0.1" ixy="0" ixz="0" iyz="0" />
      </inertial>
      <visual>
        <geometry>
          <mesh filename="../../../Model/meshes/visual/link6.obj"/>
        </geometry>
      </visual>
      <!-- <collision>
        <geometry>
          <mesh filename="../../../Model/meshes/collision/link6.obj"/>
        </geometry>
      </collision> -->
    </link>
    <link name="link7R">
      <inertial>
        <origin xyz="0 0 0.17" rpy="0 -0 0" />
        <mass value="1.8" />
        <inertia ixx="0.09" iyy="0.05" izz="0.07" ixy="0" ixz="0" iyz="0" />
      </inertial>
      <visual>
        <geometry>
          <mesh filename="../../../Model/meshes/visual/link7.obj"/>
        </geometry>
      </visual>
      <!-- <collision>
        <geometry>
          <mesh filename="../../../Model/meshes/collision/link7.obj"/>
        </geometry>
      </collision> -->
      <visual>
        <origin xyz="0 0 0.107" rpy="0 0 -0.78539816339" />
        <geometry>
          <mesh filename="../../../Model/meshes/visual/hand.obj"/>
        </geometry>
      </visual>
<!--       <collision>
        <origin xyz="0 0 0.107" rpy="0 0 -0.78539816339" />
        <geometry>
          <mesh filename="../../../Model/meshes/collision/hand.obj"/>
        </geometry>
      </collision> -->
    </link>
    <link name="leftfingerR">
      <inertial>
        <origin xyz="0 0 0.05" rpy="0 -0 0" />
        <mass value="0.1" />
        <inertia ixx="0.01" iyy="0.01" izz="0.005" ixy="0" ixz="0" iyz="0" />
      </inertial>
      <visual>
        <geometry>
          <mesh filename="../../../Model/meshes/visual/finger.obj"/>
        </geometry>
      </visual>
<!--       <collision>
        <geometry>
          <mesh filename="../../../Model/meshes/collision/finger.obj"/>
        </geometry>
      </collision> -->
    </link>
    <link name="rightfingerR">
      <inertial>
        <origin xyz="0 0 0.05" rpy="0 -0 0" />
        <mass value="0.1" />
        <inertia ixx="0.01" iyy="0.01" izz="0.005" ixy="0" ixz="0" iyz="0" />
      </inertial>
      <visual>
        <origin xyz="0 0 0" rpy="0 0 3.14159265359" />
        <geometry>
          <mesh filename="../../../Model/meshes/visual/finger.obj"/>
        </geometry>
      </visual>
<!--       <collision>
        <origin xyz="0 0 0" rpy="0 0 3.14159265359" />
        <geometry>
          <mesh filename="../../../Model/meshes/collision/finger.obj"/>
        </geometry>
      </collision> -->
    </link>

<!--     END RIGHT ARM
 -->


<!--  JOINTS
 -->

  <joint
    name="base_prismatic_x"
    type="prismatic">
    <origin
      xyz="0 0 0"
      rpy="0 0 0" />
    <parent
      link="floor" />
    <child
      link="base_x" />
    <axis
      xyz="1 0 0" />
    <limit lower="-200" upper="200" effort="1000" velocity="1000" />
  </joint>

  <joint
    name="base_prismatic_y"
    type="prismatic">
    <origin
      xyz="0 0 0"
      rpy="0 0 0" />
    <parent
      link="base_x" />
    <child
      link="base_y" />
    <axis
      xyz="0 1 0" />
    <limit lower="-200" upper="200" effort="1000" velocity="1000" />
  </joint>



<joint
    name="base_revolute"
    type="revolute">
    <origin
      xyz="0 0 0"
      rpy="0 0 0" />
    <parent
      link="base_y" />
    <child
      link="base_link" />
    <axis
      xyz="0 0 1" />
    <limit lower="-200" upper="200" effort="1000" velocity="1000" />
  </joint>



  <joint
    name="prismatic"
    type="prismatic">
    <origin
      xyz="0 0 0"
      rpy="0 0 0" />
    <parent
      link="base_link" />
    <child
      link="torso" />
    <axis
      xyz="0 0 1" />
     <limit lower="-2.967" upper="2.967" effort="176" velocity="1.7104" />
  </joint>


    <joint name="torso to rightarm" type="revolute">
      <origin rpy="1 0 0" xyz="0 0.0 0.1"/>
      <parent link="torso"/>
      <child link="link0R"/>
      <axis xyz = "0 0 1" />
      <limit lower="0" upper="0" effort="0" velocity="0" />
    </joint>



    <joint name="joint1R" type="revolute">
      <safety_controller k_position="100.0" k_velocity="40.0" soft_lower_limit="-2.8973" soft_upper_limit="2.8973"/>
      <origin rpy="0 0 0" xyz="0 0 0.333"/>
      <parent link="link0R"/>
      <child link="link1R"/>
      <axis xyz="0 0 1"/>
      <limit effort="87" lower="-2.8973" upper="2.8973" velocity="2.1750"/>
    </joint>

    <joint name="joint2R" type="revolute">
      <safety_controller k_position="100.0" k_velocity="40.0" soft_lower_limit="-1.7628" soft_upper_limit="1.7628"/>
      <origin rpy="-1.57079632679 0 0" xyz="0 0 0"/>
      <parent link="link1R"/>
      <child link="link2R"/>
      <axis xyz="0 0 1"/>
      <calibration falling="15.0" />
      <limit effort="87" lower="-1.7628" upper="1.7628" velocity="2.1750"/>
    </joint>

    <joint name="joint3R" type="revolute">
      <safety_controller k_position="100.0" k_velocity="40.0" soft_lower_limit="-2.8973" soft_upper_limit="2.8973"/>
      <origin rpy="1.57079632679 0 0" xyz="0 -0.316 0"/>
      <parent link="link2R"/>
      <child link="link3R"/>
      <axis xyz="0 0 1"/>
      <limit effort="87" lower="-2.8973" upper="2.8973" velocity="2.1750"/>
    </joint>

    <joint name="joint4R" type="revolute">
      <safety_controller k_position="100.0" k_velocity="40.0" soft_lower_limit="-3.0718" soft_upper_limit="-0.0698"/>
      <origin rpy="1.57079632679 0 0" xyz="0.0825 0 0"/>
      <parent link="link3R"/>
      <child link="link4R"/>
      <axis xyz="0 0 1"/>
      <calibration falling="-95.0" />
      <limit effort="87" lower="-3.0718" upper="-0.0698" velocity="2.1750"/>
    </joint>

    <joint name="joint5R" type="revolute">
      <safety_controller k_position="100.0" k_velocity="40.0" soft_lower_limit="-2.8973" soft_upper_limit="2.8973"/>
      <origin rpy="-1.57079632679 0 0" xyz="-0.0825 0.384 0"/>
      <parent link="link4R"/>
      <child link="link5R"/>
      <axis xyz="0 0 1"/>
      <limit effort="12" lower="-2.8973" upper="2.8973" velocity="2.6100"/>
    </joint>

    <joint name="joint6R" type="revolute">
      <safety_controller k_position="100.0" k_velocity="40.0" soft_lower_limit="-0.0175" soft_upper_limit="3.7525"/>
      <origin rpy="1.57079632679 0 0" xyz="0 0 0"/>
      <parent link="link5R"/>
      <child link="link6R"/>
      <axis xyz="0 0 1"/>
      <calibration falling="125.0" />
      <limit effort="12" lower="-0.0175" upper="3.7525" velocity="2.6100"/>
    </joint>

    <joint name="joint7R" type="revolute">
      <safety_controller k_position="100.0" k_velocity="40.0" soft_lower_limit="-2.8973" soft_upper_limit="2.8973"/>
      <origin rpy="1.57079632679 0 0" xyz="0.088 0 0"/>
      <parent link="link6R"/>
      <child link="link7R"/>
      <axis xyz="0 0 1"/>
      <limit effort="12" lower="-2.8973" upper="2.8973" velocity="2.6100"/>
    </joint>

    <joint name="finger_joint1R" type="prismatic">
      <parent link="link7R"/>
      <child link="leftfingerR"/>
      <origin xyz="0 0 0.1654" rpy="0 0 -0.78539816339"/>
      <axis xyz="0 1 0"/>
      <calibration rising="0.02" />
      <limit effort="20" lower="0.0" upper="0.04" velocity="0.2"/>
    </joint>

    <joint name="finger_joint2R" type="prismatic">
      <parent link="link7R"/>
      <child link="rightfingerR"/>
      <origin xyz="0 0 0.1654" rpy="0 0 -0.78539816339"/>
      <axis xyz="0 1 0"/>
      <calibration rising="-0.02" />
      <limit effort="20" lower="0.0" upper="0.04" velocity="0.2"/>
    </joint>


<joint name="torso to leftarm" type="revolute">
      <origin rpy="-1 0 0" xyz="0 0.0 0.1"/>
      <parent link="torso"/>
      <child link="link0L"/>
      <axis xyz = "0 0 1" />
      <limit lower="0" upper="0" effort="0" velocity="0" />
    </joint>



    <link name="link0L">
      <inertial>
        <origin xyz="0 0 0.05" rpy="0 0 0" />
        <mass value="4" />
        <inertia ixx="0.4" iyy="0.4" izz="0.4" ixy="0" ixz="0" iyz="0" />
      </inertial>
      <visual>
        <geometry>
          <mesh filename="../../../Model/meshes/visual/link0.obj"/>
        </geometry>
      </visual>
<!--       <collision>
        <geometry>
          <mesh filename="../../../Model/meshes/collision/link0.obj"/>
        </geometry>
      </collision> -->
    </link>
    <link name="link1L">
      <inertial>
        <origin xyz="0 0 -0.07" rpy="0 -0 0" />
        <mass value="3" />
        <inertia ixx="0.3" iyy="0.3" izz="0.3" ixy="0" ixz="0" iyz="0" />
      </inertial>
      <visual>
        <geometry>
          <mesh filename="../../../Model/meshes/visual/link1.obj"/>
        </geometry>
      </visual>
      <!-- <collision>
        <geometry>
          <mesh filename="../../../Model/meshes/collision/link1.obj"/>
        </geometry>
      </collision> -->
    </link>
    <link name="link2L">
      <inertial>
        <origin xyz="0 -0.1 0" rpy="0 -0 0" />
        <mass value="3" />
        <inertia ixx="0.3" iyy="0.3" izz="0.3" ixy="0" ixz="0" iyz="0" />
      </inertial>
      <visual>
        <geometry>
          <mesh filename="../../../Model/meshes/visual/link2.obj"/>
        </geometry>
      </visual>
      <!-- <collision>
        <geometry>
          <mesh filename="../../../Model/meshes/collision/link2.obj"/>
        </geometry>
      </collision> -->
    </link>
    <link name="link3L">
      <inertial>
        <origin xyz="0.04 0 -0.05" rpy="0 -0 0" />
        <mass value="2" />
        <inertia ixx="0.2" iyy="0.2" izz="0.2" ixy="0" ixz="0" iyz="0" />
      </inertial>
      <visual>
        <geometry>
          <mesh filename="../../../Model/meshes/visual/link3.obj"/>
        </geometry>
      </visual>
      <!-- <collision>
        <geometry>
          <mesh filename="../../../Model/meshes/collision/link3.obj"/>
        </geometry>
      </collision> -->
    </link>
    <link name="link4L">
      <inertial>
        <origin xyz="-0.04 0.05 0" rpy="0 -0 0" />
        <mass value="2" />
        <inertia ixx="0.2" iyy="0.2" izz="0.2" ixy="0" ixz="0" iyz="0" />
      </inertial>
      <visual>
        <geometry>
          <mesh filename="../../../Model/meshes/visual/link4.obj"/>
        </geometry>
      </visual>
      <collision>
        <geometry>
          <mesh filename="../../../Model/meshes/collision/link4.obj"/>
        </geometry>
      </collision>
    </link>
    <link name="link5L">
      <inertial>
        <origin xyz="0 0 -0.15" rpy="0 -0 0" />
        <mass value="2" />
        <inertia ixx="0.2" iyy="0.2" izz="0.2" ixy="0" ixz="0" iyz="0" />
      </inertial>
      <visual>
        <geometry>
          <mesh filename="../../../Model/meshes/visual/link5.obj"/>
        </geometry>
      </visual>
<!--       <collision>
        <geometry>
          <mesh filename="../../../Model/meshes/collision/link5.obj"/>
        </geometry>
      </collision> -->
    </link>
    <link name="link6L">
      <inertial>
        <origin xyz="0.06 0 0" rpy="0 -0 0" />
        <mass value="1.5" />
        <inertia ixx="0.1" iyy="0.1" izz="0.1" ixy="0" ixz="0" iyz="0" />
      </inertial>
      <visual>
        <geometry>
          <mesh filename="../../../Model/meshes/visual/link6.obj"/>
        </geometry>
      </visual>
      <!-- <collision>
        <geometry>
          <mesh filename="../../../Model/meshes/collision/link6.obj"/>
        </geometry>
      </collision> -->
    </link>
    <link name="link7L">
      <inertial>
        <origin xyz="0 0 0.17" rpy="0 -0 0" />
        <mass value="1.8" />
        <inertia ixx="0.09" iyy="0.05" izz="0.07" ixy="0" ixz="0" iyz="0" />
      </inertial>
      <visual>
        <geometry>
          <mesh filename="../../../Model/meshes/visual/link7.obj"/>
        </geometry>
      </visual>
      <!-- <collision>
        <geometry>
          <mesh filename="../../../Model/meshes/collision/link7.obj"/>
        </geometry>
      </collision> -->
      <visual>
        <origin xyz="0 0 0.107" rpy="0 0 -0.78539816339" />
        <geometry>
          <mesh filename="../../../Model/meshes/visual/hand.obj"/>
        </geometry>
      </visual>
<!--       <collision>
        <origin xyz="0 0 0.107" rpy="0 0 -0.78539816339" />
        <geometry>
          <mesh filename="../../../Model/meshes/collision/hand.obj"/>
        </geometry>
      </collision> -->
    </link>
    <link name="leftfingerL">
      <inertial>
        <origin xyz="0 0 0.05" rpy="0 -0 0" />
        <mass value="0.1" />
        <inertia ixx="0.01" iyy="0.01" izz="0.005" ixy="0" ixz="0" iyz="0" />
      </inertial>
      <visual>
        <geometry>
          <mesh filename="../../../Model/meshes/visual/finger.obj"/>
        </geometry>
      </visual>
<!--       <collision>
        <geometry>
          <mesh filename="../../../Model/meshes/collision/finger.obj"/>
        </geometry>
      </collision> -->
    </link>
    <link name="rightfingerL">
      <inertial>
        <origin xyz="0 0 0.05" rpy="0 -0 0" />
        <mass value="0.1" />
        <inertia ixx="0.01" iyy="0.01" izz="0.005" ixy="0" ixz="0" iyz="0" />
      </inertial>
      <visual>
        <origin xyz="0 0 0" rpy="0 0 3.14159265359" />
        <geometry>
          <mesh filename="../../../Model/meshes/visual/finger.obj"/>
        </geometry>
      </visual>
<!--       <collision>
        <origin xyz="0 0 0" rpy="0 0 3.14159265359" />
        <geometry>
          <mesh filename="../../../Model/meshes/collision/finger.obj"/>
        </geometry>
      </collision> -->
    </link>
    <joint name="joint1L" type="revolute">
      <safety_controller k_position="100.0" k_velocity="40.0" soft_lower_limit="-2.8973" soft_upper_limit="2.8973"/>
      <origin rpy="0 0 0" xyz="0 0 0.333"/>
      <parent link="link0L"/>
      <child link="link1L"/>
      <axis xyz="0 0 1"/>
      <limit effort="87" lower="-2.8973" upper="2.8973" velocity="2.1750"/>
    </joint>
    <joint name="joint2L" type="revolute">
      <safety_controller k_position="100.0" k_velocity="40.0" soft_lower_limit="-1.7628" soft_upper_limit="1.7628"/>
      <origin rpy="-1.57079632679 0 0" xyz="0 0 0"/>
      <parent link="link1L"/>
      <child link="link2L"/>
      <axis xyz="0 0 1"/>
      <calibration falling="15.0" />
      <limit effort="87" lower="-1.7628" upper="1.7628" velocity="2.1750"/>
    </joint>
    <joint name="joint3L" type="revolute">
      <safety_controller k_position="100.0" k_velocity="40.0" soft_lower_limit="-2.8973" soft_upper_limit="2.8973"/>
      <origin rpy="1.57079632679 0 0" xyz="0 -0.316 0"/>
      <parent link="link2L"/>
      <child link="link3L"/>
      <axis xyz="0 0 1"/>
      <limit effort="87" lower="-2.8973" upper="2.8973" velocity="2.1750"/>
    </joint>
    <joint name="joint4L" type="revolute">
      <safety_controller k_position="100.0" k_velocity="40.0" soft_lower_limit="-3.0718" soft_upper_limit="-0.0698"/>
      <origin rpy="1.57079632679 0 0" xyz="0.0825 0 0"/>
      <parent link="link3L"/>
      <child link="link4L"/>
      <axis xyz="0 0 1"/>
      <calibration falling="-95.0" />
      <limit effort="87" lower="-3.0718" upper="-0.0698" velocity="2.1750"/>
    </joint>
    <joint name="joint5L" type="revolute">
      <safety_controller k_position="100.0" k_velocity="40.0" soft_lower_limit="-2.8973" soft_upper_limit="2.8973"/>
      <origin rpy="-1.57079632679 0 0" xyz="-0.0825 0.384 0"/>
      <parent link="link4L"/>
      <child link="link5L"/>
      <axis xyz="0 0 1"/>
      <limit effort="12" lower="-2.8973" upper="2.8973" velocity="2.6100"/>
    </joint>
    <joint name="joint6L" type="revolute">
      <safety_controller k_position="100.0" k_velocity="40.0" soft_lower_limit="-0.0175" soft_upper_limit="3.7525"/>
      <origin rpy="1.57079632679 0 0" xyz="0 0 0"/>
      <parent link="link5L"/>
      <child link="link6L"/>
      <axis xyz="0 0 1"/>
      <calibration falling="125.0" />
      <limit effort="12" lower="-0.0175" upper="3.7525" velocity="2.6100"/>
    </joint>
    <joint name="joint7L" type="revolute">
      <safety_controller k_position="100.0" k_velocity="40.0" soft_lower_limit="-2.8973" soft_upper_limit="2.8973"/>
      <origin rpy="1.57079632679 0 0" xyz="0.088 0 0"/>
      <parent link="link6L"/>
      <child link="link7L"/>
      <axis xyz="0 0 1"/>
      <limit effort="12" lower="-2.8973" upper="2.8973" velocity="2.6100"/>
    </joint>
    <joint name="finger_joint1L" type="prismatic">
      <parent link="link7L"/>
      <child link="leftfingerL"/>
      <origin xyz="0 0 0.1654" rpy="0 0 -0.78539816339"/>
      <axis xyz="0 1 0"/>
      <calibration rising="0.02" />
      <limit effort="20" lower="0.0" upper="0.04" velocity="0.2"/>
    </joint>
    <joint name="finger_joint2L" type="prismatic">
      <parent link="link7L"/>
      <child link="rightfingerL"/>
      <origin xyz="0 0 0.1654" rpy="0 0 -0.78539816339"/>
      <axis xyz="0 1 0"/>
      <calibration rising="-0.02" />
      <limit effort="20" lower="0.0" upper="0.04" velocity="0.2"/>
      <!-- <mimic joint="finger_joint1" /> -->
    </joint>








</robot>